2020-11-28 23:11:30,046--test_register.py--65--ERROR--hanjiping_log--注册名11位该条测试用例未通过
2020-11-28 23:11:30,047--test_register.py--66--ERROR--hanjiping_log--2 != 0 within 7 places (2 difference)
Traceback (most recent call last):
  File "/Users/hanjiping/PycharmProjects/Port_test01/TestCase/test_register.py", line 49, in test_register
    self.assertAlmostEqual(expected['code'],res['code'])
  File "/opt/anaconda3/lib/python3.7/unittest/case.py", line 906, in assertAlmostEqual
    raise self.failureException(msg)
AssertionError: 2 != 0 within 7 places (2 difference)
2020-11-28 23:11:30,450--test_register.py--69--INFO--hanjiping_log--类型输入非0，1内容该条用例通过
2020-11-28 23:11:31,063--test_register.py--65--ERROR--hanjiping_log--手机号为字符串类型该条测试用例未通过
2020-11-28 23:11:31,063--test_register.py--66--ERROR--hanjiping_log--2 != 0 within 7 places (2 difference)
Traceback (most recent call last):
  File "/Users/hanjiping/PycharmProjects/Port_test01/TestCase/test_register.py", line 49, in test_register
    self.assertAlmostEqual(expected['code'],res['code'])
  File "/opt/anaconda3/lib/python3.7/unittest/case.py", line 906, in assertAlmostEqual
    raise self.failureException(msg)
AssertionError: 2 != 0 within 7 places (2 difference)
2020-11-28 23:11:34,221--test_login.py--48--ERROR--hanjiping_log--用例登录成功出现错误，错误信息为：0 != 2 within 7 places (2 difference)
2020-11-28 23:11:34,222--test_login.py--49--ERROR--hanjiping_log--0 != 2 within 7 places (2 difference)
Traceback (most recent call last):
  File "/Users/hanjiping/PycharmProjects/Port_test01/TestCase/test_login.py", line 44, in test_login
    self.assertAlmostEqual(expected['code'],res["code"])
  File "/opt/anaconda3/lib/python3.7/unittest/case.py", line 906, in assertAlmostEqual
    raise self.failureException(msg)
AssertionError: 0 != 2 within 7 places (2 difference)
2020-11-28 23:11:34,551--test_login.py--52--INFO--hanjiping_log--用例运行正常密码错误
2020-11-28 23:11:34,645--test_login.py--52--INFO--hanjiping_log--用例运行正常账号不是标准的手机号
2020-11-28 23:11:35,338--test_register.py--65--ERROR--hanjiping_log--注册成功-带注册名该条测试用例未通过
2020-11-28 23:11:35,338--test_register.py--66--ERROR--hanjiping_log--() is not true
Traceback (most recent call last):
  File "/Users/hanjiping/PycharmProjects/Port_test01/TestCase/test_register.py", line 56, in test_register
    self.assertTrue(res1)
  File "/opt/anaconda3/lib/python3.7/unittest/case.py", line 705, in assertTrue
    raise self.failureException(msg)
AssertionError: () is not true
